Workbook

Sheet kappa
A1: foaf.xml | F1: foaf_names.xml | M1: foaf.xml | N1: foaf_names.xml | O1: natural.txt | P1: natural.json | Q1: foaf.rdf | R1: foaf_names.rdf | S1: foaf.json | T1: foaf_names.json
B2: TRUE | C2: FALSE | D2: half true | G2: TRUE | H2: FALSE | I2: half true | L2: dominik | M2: =B3+B4+B5 -> 51 | N2: =G3+G4+G5 -> 54 | O2: =B13+B14+B15 -> 37 | P2: =G13+G14+G15 -> 43 | Q2: =B23+B24+B25 -> 45 | R2: =G23+G24+G25 -> 52 | S2: =B33+B34+B35 -> 50 | T2: =G33+G34+G35 -> 53
A3: TRUE | B3: =COUNTIFS(foaf.xml!$C$2:$C$61,TRUE,foaf.xml!$E$2:$E$61,TRUE) -> 51 | C3: =COUNTIFS(foaf.xml!$C$2:$C$61,TRUE,foaf.xml!$E$2:$E$61,FALSE) -> 0 | D3: =COUNTIFS(foaf.xml!$C$2:$C$61,TRUE,foaf.xml!$E$2:$E$61,"half true") -> 0 | F3: TRUE | G3: =COUNTIFS(foaf_names.xml!$C$2:$C$61,TRUE,foaf_names.xml!$E$2:$E$61,TRUE) -> 54 | H3: =COUNTIFS(foaf_names.xml!$C$2:$C$61,TRUE,foaf_names.xml!$E$2:$E$61,FALSE) -> 0 | I3: =COUNTIFS(foaf_names.xml!$C$2:$C$61,TRUE,foaf_names.xml!$E$2:$E$61,"half true") -> 0 | L3: sven | M3: =SUM(B3:D3) -> 51 | N3: =SUM(G3:I3) -> 54 | O3: =SUM(B13:D13) -> 37 | P3: =SUM(G13:I13) -> 43 | Q3: =SUM(B23:D23) -> 45 | R3: =G23+H23+I23 -> 52 | S3: =B33+C33+D33 -> 50 | T3: =G33+H33+I33 -> 54
A4: FALSE | B4: =COUNTIFS(foaf.xml!$C$2:$C$61,FALSE,foaf.xml!$E$2:$E$61,TRUE) -> 0 | C4: =COUNTIFS(foaf.xml!$C$2:$C$61,FALSE,foaf.xml!$E$2:$E$61,FALSE) -> 4 | D4: =COUNTIFS(foaf.xml!$C$2:$C$61,FALSE,foaf.xml!$E$2:$E$61,"half true") -> 0 | F4: FALSE | G4: =COUNTIFS(foaf_names.xml!$C$2:$C$61,FALSE,foaf_names.xml!$E$2:$E$61,TRUE) -> 0 | H4: =COUNTIFS(foaf_names.xml!$C$2:$C$61,FALSE,foaf_names.xml!$E$2:$E$61,FALSE) -> 4 | I4: =COUNTIFS(foaf_names.xml!$C$2:$C$61,FALSE,foaf_names.xml!$E$2:$E$61,"half true") -> 0 | L4: sum | M4: =SUM(M2:M3) -> 102 | N4: =SUM(N2:N3) -> 108 | O4: =SUM(O2:O3) -> 74 | P4: =SUM(P2:P3) -> 86 | Q4: =SUM(Q2:Q3) -> 90 | R4: =SUM(R2:R3) -> 104 | S4: =SUM(S2:S3) -> 100 | T4: =SUM(T2:T3) -> 107
A5: half true | B5: =COUNTIFS(foaf.xml!$C$2:$C$61,"half true",foaf.xml!$E$2:$E$61,TRUE) -> 0 | C5: =COUNTIFS(foaf.xml!$C$2:$C$61,"half true",foaf.xml!$E$2:$E$61,FALSE) -> 0 | D5: =COUNTIFS(foaf.xml!$C$2:$C$61,"half true",foaf.xml!$E$2:$E$61,"half true") -> 5 | F5: half true | G5: =COUNTIFS(foaf_names.xml!$C$2:$C$61,"half true",foaf_names.xml!$E$2:$E$61,TRUE) -> 0 | H5: =COUNTIFS(foaf_names.xml!$C$2:$C$61,"half true",foaf_names.xml!$E$2:$E$61,FALSE) -> 0 | I5: =COUNTIFS(foaf_names.xml!$C$2:$C$61,"half true",foaf_names.xml!$E$2:$E$61,"half true") -> 2
A6: N | B6: =SUM(B3:D5) -> 60 | F6: N | G6: =SUM(G3:I5) -> 60
A7: Po | B7: =(B3+C4+D5)/B6 -> 1 | F7: Po | G7: =(G3+H4+I5)/G6 -> 1 | M7: data from all attempts
A8: Pe | B8: =((SUM(B3:D3)*SUM(B3:B5))+(SUM(B4:D4)*SUM(C3:C5))+(SUM(B5:D5)*SUM(D3:D5)))/(B6^2) -> 0.73388889 | F8: Pe | G8: =((SUM(G3:I3)*SUM(G3:G5))+(SUM(G4:I4)*SUM(H3:H5))+(SUM(G5:I5)*SUM(I3:I5)))/(G6^2) -> 0.81555556 | M8: foaf.xml | N8: foaf_names.xml | O8: natural.txt | P8: natural.json | Q8: foaf.rdf | R8: foaf_names.rdf | S8: foaf.json | T8: foaf_names.json
A9: Kappa | B9: =(B7-B8)/(1-B8) -> 1 | F9: Kappa | G9: =(G7-G8)/(1-G8) -> 1 | M9: 102 | N9: 108 | O9: 74 | P9: 86 | Q9: 90 | R9: 104 | S9: 100 | T9: 107
M10: 102 | N10: 103 | O10: 61 | P10: 82 | Q10: 96 | R10: 100 | S10: 101 | T10: 106
A11: natural.txt | F11: natural.json | M11: 102 | N11: 108 | O11: 62 | P11: 80 | Q11: 92 | R11: 98 | S11: 98 | T11: 108
B12: TRUE | C12: FALSE | D12: half true | G12: TRUE | H12: FALSE | I12: half true | M12: 102 | N12: 106 | O12: 72 | P12: 78 | Q12: 94 | R12: 102 | S12: 98 | T12: 108
A13: TRUE | B13: =COUNTIFS(natural.txt!$C$2:$C$61,TRUE,natural.txt!$E$2:$E$61,TRUE) -> 37 | C13: =COUNTIFS(natural.txt!$C$2:$C$61,TRUE,natural.txt!$E$2:$E$61,FALSE) -> 0 | D13: =COUNTIFS(natural.txt!$C$2:$C$61,TRUE,natural.txt!$E$2:$E$61,"half true") -> 0 | F13: TRUE | G13: =COUNTIFS(natural.json!$C$2:$C$61,TRUE,natural.json!$E$2:$E$61,TRUE) -> 43 | H13: =COUNTIFS(natural.json!$C$2:$C$61,TRUE,natural.json!$E$2:$E$61,FALSE) -> 0 | I13: =COUNTIFS(natural.json!$C$2:$C$61,TRUE,natural.json!$E$2:$E$61,"half true") -> 0 | M13: 102 | N13: 110 | O13: 58 | P13: 80 | Q13: 94 | R13: 100 | S13: 104 | T13: 110
A14: FALSE | B14: =COUNTIFS(natural.txt!$C$2:$C$61,FALSE,natural.txt!$E$2:$E$61,TRUE) -> 0 | C14: =COUNTIFS(natural.txt!$C$2:$C$61,FALSE,natural.txt!$E$2:$E$61,FALSE) -> 20 | D14: =COUNTIFS(natural.txt!$C$2:$C$61,FALSE,natural.txt!$E$2:$E$61,"half true") -> 0 | F14: FALSE | G14: =COUNTIFS(natural.json!$C$2:$C$61,FALSE,natural.json!$E$2:$E$61,TRUE) -> 0 | H14: =COUNTIFS(natural.json!$C$2:$C$61,FALSE,natural.json!$E$2:$E$61,FALSE) -> 13 | I14: =COUNTIFS(natural.json!$C$2:$C$61,FALSE,natural.json!$E$2:$E$61,"half true") -> 0 | L14: sum_true | M14: =SUM(M9:M13) -> 510 | N14: =SUM(N9:N13) -> 535 | O14: =SUM(O9:O13) -> 327 | P14: =SUM(P9:P13) -> 406 | Q14: =SUM(Q9:Q13) -> 466 | R14: =SUM(R9:R13) -> 504 | S14: =SUM(S9:S13) -> 501 | T14: =SUM(T9:T13) -> 539
A15: half true | B15: =COUNTIFS(natural.txt!$C$2:$C$61,"half true",natural.txt!$E$2:$E$61,TRUE) -> 0 | C15: =COUNTIFS(natural.txt!$C$2:$C$61,"half true",natural.txt!$E$2:$E$61,FALSE) -> 0 | D15: =COUNTIFS(natural.txt!$C$2:$C$61,"half true",natural.txt!$E$2:$E$61,"half true") -> 3 | F15: half true | G15: =COUNTIFS(natural.json!$C$2:$C$61,"half true",natural.json!$E$2:$E$61,TRUE) -> 0 | H15: =COUNTIFS(natural.json!$C$2:$C$61,"half true",natural.json!$E$2:$E$61,FALSE) -> 0 | I15: =COUNTIFS(natural.json!$C$2:$C$61,"half true",natural.json!$E$2:$E$61,"half true") -> 4 | L15: sum_data | M15: =2*5*B6 -> 600 | N15: =M15 -> 600 | O15: =N15 -> 600 | P15: =O15 -> 600 | Q15: =P15 -> 600 | R15: =Q15 -> 600 | S15: =R15 -> 600 | T15: =S15 -> 600
A16: N | B16: =SUM(B13:D15) -> 60 | F16: N | G16: =SUM(G13:I15) -> 60 | L16: accuracy | M16: =M14/M15 -> 0.85 | N16: =N14/N15 -> 0.89166667 | O16: =O14/O15 -> 0.545 | P16: =P14/P15 -> 0.67666667 | Q16: =Q14/Q15 -> 0.77666667 | R16: =R14/R15 -> 0.84 | S16: =S14/S15 -> 0.835 | T16: =T14/T15 -> 0.89833333
A17: Po | B17: =(B13+C14+D15)/B16 -> 1 | F17: Po | G17: =(G13+H14+I15)/G16 -> 1
A18: Pe | B18: =((SUM(B13:D13)*SUM(B13:B15))+(SUM(B14:D14)*SUM(C13:C15))+(SUM(B15:D15)*SUM(D13:D15)))/(B16^2) -> 0.49388889 | F18: Pe | G18: =((SUM(G13:I13)*SUM(G13:G15))+(SUM(G14:I14)*SUM(H13:H15))+(SUM(G15:I15)*SUM(I13:I15)))/(G16^2) -> 0.565
A19: Kappa | B19: =(B17-B18)/(1-B18) -> 1 | F19: Kappa | G19: =(G17-G18)/(1-G18) -> 1
A21: foaf.rdf | F21: foaf_names.rdf
B22: TRUE | C22: FALSE | D22: half true | G22: TRUE | H22: FALSE | I22: half true
A23: TRUE | B23: =COUNTIFS(foaf.rdf!$C$2:$C$61,TRUE,foaf.rdf!$E$2:$E$61,TRUE) -> 45 | C23: =COUNTIFS(foaf.rdf!$C$2:$C$61,TRUE,foaf.rdf!$E$2:$E$61,FALSE) -> 0 | D23: =COUNTIFS(foaf.rdf!$C$2:$C$61,TRUE,foaf.rdf!$E$2:$E$61,"half true") -> 0 | F23: TRUE | G23: =COUNTIFS(foaf_names.rdf!$C$2:$C$61,TRUE,foaf_names.rdf!$E$2:$E$61,TRUE) -> 52 | H23: =COUNTIFS(foaf_names.rdf!$C$2:$C$61,TRUE,foaf_names.rdf!$E$2:$E$61,FALSE) -> 0 | I23: =COUNTIFS(foaf_names.rdf!$C$2:$C$61,TRUE,foaf_names.rdf!$E$2:$E$61,"half true") -> 0
A24: FALSE | B24: =COUNTIFS(foaf.rdf!$C$2:$C$61,FALSE,foaf.rdf!$E$2:$E$61,TRUE) -> 0 | C24: =COUNTIFS(foaf.rdf!$C$2:$C$61,FALSE,foaf.rdf!$E$2:$E$61,FALSE) -> 12 | D24: =COUNTIFS(foaf.rdf!$C$2:$C$61,FALSE,foaf.rdf!$E$2:$E$61,"half true") -> 0 | F24: FALSE | G24: =COUNTIFS(foaf_names.rdf!$C$2:$C$61,FALSE,foaf_names.rdf!$E$2:$E$61,TRUE) -> 0 | H24: =COUNTIFS(foaf_names.rdf!$C$2:$C$61,FALSE,foaf_names.rdf!$E$2:$E$61,FALSE) -> 6 | I24: =COUNTIFS(foaf_names.rdf!$C$2:$C$61,FALSE,foaf_names.rdf!$E$2:$E$61,"half true") -> 0
A25: half true | B25: =COUNTIFS(foaf.rdf!$C$2:$C$61,"half true",foaf.rdf!$E$2:$E$61,TRUE) -> 0 | C25: =COUNTIFS(foaf.rdf!$C$2:$C$61,"half true",foaf.rdf!$E$2:$E$61,FALSE) -> 0 | D25: =COUNTIFS(foaf.rdf!$C$2:$C$61,"half true",foaf.rdf!$E$2:$E$61,"half true") -> 3 | F25: half true | G25: =COUNTIFS(foaf_names.rdf!$C$2:$C$61,"half true",foaf_names.rdf!$E$2:$E$61,TRUE) -> 0 | H25: =COUNTIFS(foaf_names.rdf!$C$2:$C$61,"half true",foaf_names.rdf!$E$2:$E$61,FALSE) -> 0 | I25: =COUNTIFS(foaf_names.rdf!$C$2:$C$61,"half true",foaf_names.rdf!$E$2:$E$61,"half true") -> 2
A26: N | B26: =SUM(B23:D25) -> 60 | F26: N | G26: =SUM(G23:I25) -> 60
A27: Po | B27: =(B23+C24+D25)/B26 -> 1 | F27: Po | G27: =(G23+H24+I25)/G26 -> 1
A28: Pe | B28: =((SUM(B23:D23)*SUM(B23:B25))+(SUM(B24:D24)*SUM(C23:C25))+(SUM(B25:D25)*SUM(D23:D25)))/(B26^2) -> 0.605 | F28: Pe | G28: =((SUM(G23:I23)*SUM(G23:G25))+(SUM(G24:I24)*SUM(H23:H25))+(SUM(G25:I25)*SUM(I23:I25)))/(G26^2) -> 0.76222222
A29: Kappa | B29: =(B27-B28)/(1-B28) -> 1 | F29: Kappa | G29: =(G27-G28)/(1-G28) -> 1
A31: foaf.json | F31: foaf_names.json
B32: TRUE | C32: FALSE | D32: half true | G32: TRUE | H32: FALSE | I32: half true
A33: TRUE | B33: =COUNTIFS(foaf.json!$C$2:$C$61,TRUE,foaf.json!$E$2:$E$61,TRUE) -> 50 | C33: =COUNTIFS(foaf.json!$C$2:$C$61,TRUE,foaf.json!$E$2:$E$61,FALSE) -> 0 | D33: =COUNTIFS(foaf.json!$C$2:$C$61,TRUE,foaf.json!$E$2:$E$61,"half true") -> 0 | F33: TRUE | G33: =COUNTIFS(foaf_names.json!$C$2:$C$61,TRUE,foaf_names.json!$E$2:$E$61,TRUE) -> 53 | H33: =COUNTIFS(foaf_names.json!$C$2:$C$61,TRUE,foaf_names.json!$E$2:$E$61,FALSE) -> 0 | I33: =COUNTIFS(foaf_names.json!$C$2:$C$61,TRUE,foaf_names.json!$E$2:$E$61,"half true") -> 1
A34: FALSE | B34: =COUNTIFS(foaf.json!$C$2:$C$61,FALSE,foaf.json!$E$2:$E$61,TRUE) -> 0 | C34: =COUNTIFS(foaf.json!$C$2:$C$61,FALSE,foaf.json!$E$2:$E$61,FALSE) -> 3 | D34: =COUNTIFS(foaf.json!$C$2:$C$61,FALSE,foaf.json!$E$2:$E$61,"half true") -> 0 | F34: FALSE | G34: =COUNTIFS(foaf_names.json!$C$2:$C$61,FALSE,foaf_names.json!$E$2:$E$61,TRUE) -> 0 | H34: =COUNTIFS(foaf_names.json!$C$2:$C$61,FALSE,foaf_names.json!$E$2:$E$61,FALSE) -> 2 | I34: =COUNTIFS(foaf_names.json!$C$2:$C$61,FALSE,foaf_names.json!$E$2:$E$61,"half true") -> 0
A35: half true | B35: =COUNTIFS(foaf.json!$C$2:$C$61,"half true",foaf.json!$E$2:$E$61,TRUE) -> 0 | C35: =COUNTIFS(foaf.json!$C$2:$C$61,"half true",foaf.json!$E$2:$E$61,FALSE) -> 0 | D35: =COUNTIFS(foaf.json!$C$2:$C$61,"half true",foaf.json!$E$2:$E$61,"half true") -> 7 | F35: half true | G35: =COUNTIFS(foaf_names.json!$C$2:$C$61,"half true",foaf_names.json!$E$2:$E$61,TRUE) -> 0 | H35: =COUNTIFS(foaf_names.json!$C$2:$C$61,"half true",foaf_names.json!$E$2:$E$61,FALSE) -> 1 | I35: =COUNTIFS(foaf_names.json!$C$2:$C$61,"half true",foaf_names.json!$E$2:$E$61,"half true") -> 3
A36: N | B36: =SUM(B33:D35) -> 60 | F36: N | G36: =SUM(G33:I35) -> 60
A37: Po | B37: =(B33+C34+D35)/B36 -> 1 | F37: Po | G37: =(G33+H34+I35)/G36 -> 0.96666667
A38: Pe | B38: =((SUM(B33:D33)*SUM(B33:B35))+(SUM(B34:D34)*SUM(C33:C35))+(SUM(B35:D35)*SUM(D33:D35)))/(B36^2) -> 0.71055556 | F38: Pe | G38: =((SUM(G33:I33)*SUM(G33:G35))+(SUM(G34:I34)*SUM(H33:H35))+(SUM(G35:I35)*SUM(I33:I35)))/(G36^2) -> 0.80111111
A39: Kappa | B39: =(B37-B38)/(1-B38) -> 1 | F39: Kappa | G39: =(G37-G38)/(1-G38) -> 0.83240223
A41: OVERALL
B42: TRUE | C42: FALSE | D42: half true
A43: TRUE | B43: =B3+G3+B13+G13+B23+G23+B33+G33 -> 385 | C43: =C3+H3+C13+H13+C23+H23+C33+H33 -> 0 | D43: =D3+I3+D13+I13+D23+I23+D33+I33 -> 1
...

Sheet foaf.xml
A1: prompt | B1: answer | C1: validity | D1: node | E1: validity_ds
A2: What is Saša Škrtić's first name? | B2: Saša | C2: =TRUE() -> TRUE | E2: =TRUE() -> TRUE
A3: What is Saša Škrtić's last name? | B3: Škrtić | C3: =TRUE() -> TRUE | E3: =TRUE() -> TRUE
A4: What is Saša Škrtić's age? | B4: 17 | C4: =TRUE() -> TRUE | E4: =TRUE() -> TRUE
A5: What is Saša Škrtić's gender? | B5: MALE | C5: =TRUE() -> TRUE | E5: =TRUE() -> TRUE
A6: List all Saša Škrtić's friends. | B6: 1. Duje Ravlić 2. | C6: half true | E6: half true
A7: How many friends does Saša Škrtić have? | B7: Saša has 4 friends. | C7: =TRUE() -> TRUE | E7: =TRUE() -> TRUE
A8: What is Duje Ravlić's first name? | B8: Duje | C8: =TRUE() -> TRUE | E8: =TRUE() -> TRUE
A9: What is Duje Ravlić's last name? | B9: Ravlić | C9: =TRUE() -> TRUE | E9: =TRUE() -> TRUE
A10: What is Duje Ravlić's age? | B10: 18 | C10: =TRUE() -> TRUE | E10: =TRUE() -> TRUE
A11: What is Duje Ravlić's gender? | B11: MALE | C11: =TRUE() -> TRUE | E11: =TRUE() -> TRUE
A12: List all Duje Ravlić's friends. | B12: Duje Ravlić's friends: - Sa | C12: half true | E12: half true
A13: How many friends does Duje Ravlić have? | B13: Duje Ravlić has 3 friends. | C13: =TRUE() -> TRUE | E13: =TRUE() -> TRUE
A14: What is Eduard Tutić's first name? | B14: Eduard | C14: =TRUE() -> TRUE | E14: =TRUE() -> TRUE
A15: What is Eduard Tutić's last name? | B15: Tutić. | C15: =TRUE() -> TRUE | E15: =TRUE() -> TRUE
A16: What is Eduard Tutić's age? | B16: 21 | C16: =TRUE() -> TRUE | E16: =TRUE() -> TRUE
A17: What is Eduard Tutić's gender? | B17: MALE | C17: =TRUE() -> TRUE | E17: =TRUE() -> TRUE
A18: List all Eduard Tutić's friends. | B18: Human id="2" - Human id=" | C18: =FALSE() -> FALSE | E18: =FALSE() -> FALSE
A19: How many friends does Eduard Tutić have? | B19: Eduard Tutić has 4 friends | C19: =TRUE() -> TRUE | E19: =TRUE() -> TRUE
A20: What is Zoran Goreta's first name? | B20: Zoran | C20: =TRUE() -> TRUE | E20: =TRUE() -> TRUE
A21: What is Zoran Goreta's last name? | B21: Goreta | C21: =TRUE() -> TRUE | E21: =TRUE() -> TRUE
A22: What is Zoran Goreta's age? | B22: 39 | C22: =TRUE() -> TRUE | E22: =TRUE() -> TRUE
A23: What is Zoran Goreta's gender? | B23: MALE | C23: =TRUE() -> TRUE | E23: =TRUE() -> TRUE
A24: List all Zoran Goreta's friends. | B24: Zoran Goreta's friends: - Duje | C24: =FALSE() -> FALSE | E24: =FALSE() -> FALSE
A25: How many friends does Zoran Goreta have? | B25: Zoran Goreta has 2 friends. | C25: =TRUE() -> TRUE | E25: =TRUE() -> TRUE
A26: What is Ivo Čelina's first name? | B26: Ivo | C26: =TRUE() -> TRUE | E26: =TRUE() -> TRUE
A27: What is Ivo Čelina's last name? | B27: Čelina | C27: =TRUE() -> TRUE | E27: =TRUE() -> TRUE
A28: What is Ivo Čelina's age? | B28: 24 | C28: =TRUE() -> TRUE | E28: =TRUE() -> TRUE
A29: What is Ivo Čelina's gender? | B29: MALE. | C29: =TRUE() -> TRUE | E29: =TRUE() -> TRUE
A30: List all Ivo Čelina's friends. | B30: Duje Ravlić, Jagoda Dražen | C30: half true | E30: half true
A31: How many friends does Ivo Čelina have? | B31: Ivo has 3 friends. | C31: =TRUE() -> TRUE | E31: =TRUE() -> TRUE
A32: What is Jagoda Draženović's first name? | B32: Jagoda. | C32: =TRUE() -> TRUE | E32: =TRUE() -> TRUE
A33: What is Jagoda Draženović's last name? | B33: Draženović | C33: =TRUE() -> TRUE | E33: =TRUE() -> TRUE
A34: What is Jagoda Draženović's age? | B34: 11 | C34: =TRUE() -> TRUE | E34: =TRUE() -> TRUE
A35: What is Jagoda Draženović's gender? | B35: FEMALE | C35: =TRUE() -> TRUE | E35: =TRUE() -> TRUE
A36: List all Jagoda Draženović's friends. | B36: Jagoda's friends: - Saš | C36: half true | E36: half true
A37: How many friends does Jagoda Draženović have? | B37: Jagoda has 2 friends. | C37: =TRUE() -> TRUE | E37: =TRUE() -> TRUE
A38: What is Monika Rimac's first name? | B38: Monika. | C38: =TRUE() -> TRUE | E38: =TRUE() -> TRUE
A39: What is Monika Rimac's last name? | B39: Rimac | C39: =TRUE() -> TRUE | E39: =TRUE() -> TRUE
A40: What is Monika Rimac's age? | B40: 10 | C40: =TRUE() -> TRUE | E40: =TRUE() -> TRUE
...

Sheet natural.txt
A1: prompt | B1: answer | C1: validity | D1: note | E1: validity_ds
A2: What is Saša Škrtić's first name? | B2: Saša | C2: =TRUE() -> TRUE | E2: =TRUE() -> TRUE
A3: What is Saša Škrtić's last name? | B3: Škrtić | C3: =TRUE() -> TRUE | E3: =TRUE() -> TRUE
A4: What is Saša Škrtić's age? | B4: 17 years old. | C4: =TRUE() -> TRUE | E4: =TRUE() -> TRUE
A5: What is Saša Škrtić's gender? | B5: Male. | C5: =TRUE() -> TRUE | E5: =TRUE() -> TRUE
A6: List all Saša Škrtić's friends. | B6: 1. Monika Rimac 2. Du | C6: half true | E6: half true
A7: How many friends does Saša Škrtić have? | B7: At least 6. | C7: =FALSE() -> FALSE | E7: =FALSE() -> FALSE
A8: What is Duje Ravlić's first name? | B8: Not mentioned. | C8: =FALSE() -> FALSE | E8: =FALSE() -> FALSE
A9: What is Duje Ravlić's last name? | B9: Ravlić | C9: =TRUE() -> TRUE | E9: =TRUE() -> TRUE
A10: What is Duje Ravlić's age? | B10: Not mentioned. | C10: =FALSE() -> FALSE | E10: =FALSE() -> FALSE
A11: What is Duje Ravlić's gender? | B11: Male. | C11: =TRUE() -> TRUE | E11: =TRUE() -> TRUE
A12: List all Duje Ravlić's friends. | B12: 1. Mirjam Devčić 2. | C12: =TRUE() -> TRUE | E12: =TRUE() -> TRUE
A13: How many friends does Duje Ravlić have? | B13: 6 | C13: =FALSE() -> FALSE | E13: =FALSE() -> FALSE
A14: What is Eduard Tutić's first name? | B14: Eduard | C14: =TRUE() -> TRUE | E14: =TRUE() -> TRUE
A15: What is Eduard Tutić's last name? | B15: Tutić | C15: =TRUE() -> TRUE | E15: =TRUE() -> TRUE
A16: What is Eduard Tutić's age? | B16: 21 years old. | C16: =TRUE() -> TRUE | E16: =TRUE() -> TRUE
A17: What is Eduard Tutić's gender? | B17: Male. | C17: =TRUE() -> TRUE | E17: =TRUE() -> TRUE
A18: List all Eduard Tutić's friends. | B18: Eduard Tutić's friends: 1 | C18: =FALSE() -> FALSE | E18: =FALSE() -> FALSE
A19: How many friends does Eduard Tutić have? | B19: 7 | C19: =FALSE() -> FALSE | E19: =FALSE() -> FALSE
A20: What is Zoran Goreta's first name? | B20: Zoran. | C20: =TRUE() -> TRUE | E20: =TRUE() -> TRUE
A21: What is Zoran Goreta's last name? | B21: Goreta. | C21: =TRUE() -> TRUE | E21: =TRUE() -> TRUE
A22: What is Zoran Goreta's age? | B22: 39 | C22: =TRUE() -> TRUE | E22: =TRUE() -> TRUE
A23: What is Zoran Goreta's gender? | B23: Male. | C23: =TRUE() -> TRUE | E23: =TRUE() -> TRUE
A24: List all Zoran Goreta's friends. | B24: Saša Škrtić, Eduard | C24: =TRUE() -> TRUE | E24: =TRUE() -> TRUE
A25: How many friends does Zoran Goreta have? | B25: 6 | C25: =FALSE() -> FALSE | E25: =FALSE() -> FALSE
A26: What is Ivo Čelina's first name? | B26: Not mentioned. | C26: =FALSE() -> FALSE | E26: =FALSE() -> FALSE
A27: What is Ivo Čelina's last name? | B27: Not mentioned. | C27: =FALSE() -> FALSE | E27: =FALSE() -> FALSE
A28: What is Ivo Čelina's age? | B28: 24 years old. | C28: =TRUE() -> TRUE | E28: =TRUE() -> TRUE
A29: What is Ivo Čelina's gender? | B29: Male. | C29: =TRUE() -> TRUE | E29: =TRUE() -> TRUE
A30: List all Ivo Čelina's friends. | B30: Duje Ravlić, Jagoda Dražen | C30: half true | E30: half true
A31: How many friends does Ivo Čelina have? | B31: 8. | C31: =FALSE() -> FALSE | E31: =FALSE() -> FALSE
A32: What is Jagoda Draženović's first name? | B32: Jagoda | C32: =TRUE() -> TRUE | E32: =TRUE() -> TRUE
A33: What is Jagoda Draženović's last name? | B33: Draženović. | C33: =TRUE() -> TRUE | E33: =TRUE() -> TRUE
A34: What is Jagoda Draženović's age? | B34: 11 years old. | C34: =TRUE() -> TRUE | E34: =TRUE() -> TRUE
A35: What is Jagoda Draženović's gender? | B35: Female. | C35: =TRUE() -> TRUE | E35: =TRUE() -> TRUE
A36: List all Jagoda Draženović's friends. | B36: Ivo Čelina, Saša Š | C36: =TRUE() -> TRUE | E36: =TRUE() -> TRUE
A37: How many friends does Jagoda Draženović have? | B37: 6. | C37: =FALSE() -> FALSE | E37: =FALSE() -> FALSE
A38: What is Monika Rimac's first name? | B38: Not mentioned. | C38: =FALSE() -> FALSE | E38: =FALSE() -> FALSE
A39: What is Monika Rimac's last name? | B39: Rimac | C39: =TRUE() -> TRUE | E39: =TRUE() -> TRUE
A40: What is Monika Rimac's age? | B40: 10 years old. | C40: =TRUE() -> TRUE | E40: =TRUE() -> TRUE
...

Sheet foaf.rdf
A1: prompt | B1: answer | C1: validity | D1: note | E1: validity_ds
A2: What is Saša Škrtić's first name? | B2: Saša | C2: =TRUE() -> TRUE | E2: =TRUE() -> TRUE
A3: What is Saša Škrtić's last name? | B3: Škrtić | C3: =TRUE() -> TRUE | E3: =TRUE() -> TRUE
A4: What is Saša Škrtić's age? | B4: 17 | C4: =TRUE() -> TRUE | E4: =TRUE() -> TRUE
A5: What is Saša Škrtić's gender? | B5: MALE. | C5: =TRUE() -> TRUE | E5: =TRUE() -> TRUE
A6: List all Saša Škrtić's friends. | B6: Duje Ravlić, Jagoda Dražen | C6: half true | E6: half true
A7: How many friends does Saša Škrtić have? | B7: 6 | C7: =FALSE() -> FALSE | E7: =FALSE() -> FALSE
A8: What is Duje Ravlić's first name? | B8: Duje. | C8: =TRUE() -> TRUE | E8: =TRUE() -> TRUE
A9: What is Duje Ravlić's last name? | B9: Ravlić. | C9: =TRUE() -> TRUE | E9: =TRUE() -> TRUE
A10: What is Duje Ravlić's age? | B10: 18 | C10: =TRUE() -> TRUE | E10: =TRUE() -> TRUE
A11: What is Duje Ravlić's gender? | B11: MALE | C11: =TRUE() -> TRUE | E11: =TRUE() -> TRUE
A12: List all Duje Ravlić's friends. | B12: Duje Ravlić's friends: 1 | C12: =FALSE() -> FALSE | E12: =FALSE() -> FALSE
A13: How many friends does Duje Ravlić have? | B13: He has 4 friends. | C13: =FALSE() -> FALSE | E13: =FALSE() -> FALSE
A14: What is Eduard Tutić's first name? | B14: Eduard | C14: =TRUE() -> TRUE | E14: =TRUE() -> TRUE
A15: What is Eduard Tutić's last name? | B15: Tutić. | C15: =TRUE() -> TRUE | E15: =TRUE() -> TRUE
A16: What is Eduard Tutić's age? | B16: 21. | C16: =TRUE() -> TRUE | E16: =TRUE() -> TRUE
A17: What is Eduard Tutić's gender? | B17: MALE. | C17: =TRUE() -> TRUE | E17: =TRUE() -> TRUE
A18: List all Eduard Tutić's friends. | B18: Zoran Goreta, Ivo Čelina | C18: half true | E18: half true
A19: How many friends does Eduard Tutić have? | B19: 9 | C19: =FALSE() -> FALSE | E19: =FALSE() -> FALSE
A20: What is Zoran Goreta's first name? | B20: Zoran's first name is Duje. | C20: =FALSE() -> FALSE | D20: what?? | E20: =FALSE() -> FALSE
A21: What is Zoran Goreta's last name? | B21: Goreta. | C21: =TRUE() -> TRUE | E21: =TRUE() -> TRUE
A22: What is Zoran Goreta's age? | B22: 39 | C22: =TRUE() -> TRUE | E22: =TRUE() -> TRUE
A23: What is Zoran Goreta's gender? | B23: MALE | C23: =TRUE() -> TRUE | E23: =TRUE() -> TRUE
A24: List all Zoran Goreta's friends. | B24: #person3 | C24: =FALSE() -> FALSE | E24: =FALSE() -> FALSE
A25: How many friends does Zoran Goreta have? | B25: 2 (#person0, #person2) | C25: =TRUE() -> TRUE | E25: =TRUE() -> TRUE
A26: What is Ivo Čelina's first name? | B26: Ivo | C26: =TRUE() -> TRUE | E26: =TRUE() -> TRUE
A27: What is Ivo Čelina's last name? | B27: Čelina | C27: =TRUE() -> TRUE | E27: =TRUE() -> TRUE
A28: What is Ivo Čelina's age? | B28: 24 | C28: =TRUE() -> TRUE | E28: =TRUE() -> TRUE
A29: What is Ivo Čelina's gender? | B29: MALE | C29: =TRUE() -> TRUE | E29: =TRUE() -> TRUE
A30: List all Ivo Čelina's friends. | B30: Ivo Čelina's friends: person2 | C30: half true | E30: half true
A31: How many friends does Ivo Čelina have? | B31: 6 | C31: =FALSE() -> FALSE | E31: =FALSE() -> FALSE
A32: What is Jagoda Draženović's first name? | B32: Jagoda. | C32: =TRUE() -> TRUE | E32: =TRUE() -> TRUE
A33: What is Jagoda Draženović's last name? | B33: Draženović | C33: =TRUE() -> TRUE | E33: =TRUE() -> TRUE
A34: What is Jagoda Draženović's age? | B34: 11 | C34: =TRUE() -> TRUE | E34: =TRUE() -> TRUE
A35: What is Jagoda Draženović's gender? | B35: FEMALE | C35: =TRUE() -> TRUE | E35: =TRUE() -> TRUE
A36: List all Jagoda Draženović's friends. | B36: Duje Ravlić, Ivo Čel | C36: =FALSE() -> FALSE | E36: =FALSE() -> FALSE
A37: How many friends does Jagoda Draženović have? | B37: 2 | C37: =TRUE() -> TRUE | E37: =TRUE() -> TRUE
A38: What is Monika Rimac's first name? | B38: Monika | C38: =TRUE() -> TRUE | E38: =TRUE() -> TRUE
A39: What is Monika Rimac's last name? | B39: Rimac. | C39: =TRUE() -> TRUE | E39: =TRUE() -> TRUE
A40: What is Monika Rimac's age? | B40: 10 | C40: =TRUE() -> TRUE | E40: =TRUE() -> TRUE
...

Sheet foaf.json
A1: prompt | B1: answer | C1: validity | D1: note | E1: validity_ds
A2: What is Saša Škrtić's first name? | B2: Saša. | C2: =TRUE() -> TRUE | E2: =TRUE() -> TRUE
A3: What is Saša Škrtić's last name? | B3: Škrtić. | C3: =TRUE() -> TRUE | E3: =TRUE() -> TRUE
A4: What is Saša Škrtić's age? | B4: 17 | C4: =TRUE() -> TRUE | E4: =TRUE() -> TRUE
A5: What is Saša Škrtić's gender? | B5: MALE | C5: =TRUE() -> TRUE | E5: =TRUE() -> TRUE
A6: List all Saša Škrtić's friends. | B6: 0, 3, 5, 6 | C6: half true | E6: half true
A7: How many friends does Saša Škrtić have? | B7: Saša has 4 friends. | C7: =TRUE() -> TRUE | E7: TRUE
A8: What is Duje Ravlić's first name? | B8: Duje. | C8: =TRUE() -> TRUE | E8: =TRUE() -> TRUE
A9: What is Duje Ravlić's last name? | B9: Ravlić | C9: =TRUE() -> TRUE | E9: =TRUE() -> TRUE
A10: What is Duje Ravlić's age? | B10: 18 years old. | C10: =TRUE() -> TRUE | E10: =TRUE() -> TRUE
A11: What is Duje Ravlić's gender? | B11: MALE | C11: =TRUE() -> TRUE | E11: =TRUE() -> TRUE
A12: List all Duje Ravlić's friends. | B12: 1, 4, 9 | C12: half true | E12: half true
A13: How many friends does Duje Ravlić have? | B13: Duje Ravlić has 3 friends. | C13: =TRUE() -> TRUE | E13: TRUE
A14: What is Eduard Tutić's first name? | B14: Eduard | C14: =TRUE() -> TRUE | E14: =TRUE() -> TRUE
A15: What is Eduard Tutić's last name? | B15: Tutić | C15: =TRUE() -> TRUE | E15: =TRUE() -> TRUE
A16: What is Eduard Tutić's age? | B16: 21 | C16: =TRUE() -> TRUE | E16: =TRUE() -> TRUE
A17: What is Eduard Tutić's gender? | B17: MALE | C17: =TRUE() -> TRUE | E17: =TRUE() -> TRUE
A18: List all Eduard Tutić's friends. | B18: 3, 4, 6, 8 | C18: half true | E18: half true
A19: How many friends does Eduard Tutić have? | B19: Eduard Tutić has 4 friends | C19: =TRUE() -> TRUE | E19: TRUE
A20: What is Zoran Goreta's first name? | B20: Zoran. | C20: =TRUE() -> TRUE | E20: =TRUE() -> TRUE
A21: What is Zoran Goreta's last name? | B21: Goreta | C21: =TRUE() -> TRUE | E21: =TRUE() -> TRUE
A22: What is Zoran Goreta's age? | B22: 39 | C22: =TRUE() -> TRUE | E22: =TRUE() -> TRUE
A23: What is Zoran Goreta's gender? | B23: MALE | C23: =TRUE() -> TRUE | E23: =TRUE() -> TRUE
A24: List all Zoran Goreta's friends. | B24: Zoran Goreta's friends: Duje Rav | C24: =FALSE() -> FALSE | E24: FALSE
A25: How many friends does Zoran Goreta have? | B25: Zoran has 2 friends. | C25: =TRUE() -> TRUE | E25: TRUE
A26: What is Ivo Čelina's first name? | B26: Ivo | C26: =TRUE() -> TRUE | E26: =TRUE() -> TRUE
A27: What is Ivo Čelina's last name? | B27: Čelina | C27: =TRUE() -> TRUE | E27: =TRUE() -> TRUE
A28: What is Ivo Čelina's age? | B28: 24 | C28: =TRUE() -> TRUE | E28: =TRUE() -> TRUE
A29: What is Ivo Čelina's gender? | B29: MALE. | C29: =TRUE() -> TRUE | E29: =TRUE() -> TRUE
A30: List all Ivo Čelina's friends. | B30: 1, 2, 4, 5 | C30: half true | E30: half true
A31: How many friends does Ivo Čelina have? | B31: Ivo has 3 friends. | C31: =TRUE() -> TRUE | E31: =TRUE() -> TRUE
A32: What is Jagoda Draženović's first name? | B32: Jagoda | C32: =TRUE() -> TRUE | E32: =TRUE() -> TRUE
A33: What is Jagoda Draženović's last name? | B33: Draženović | C33: =TRUE() -> TRUE | E33: =TRUE() -> TRUE
A34: What is Jagoda Draženović's age? | B34: 11 | C34: =TRUE() -> TRUE | E34: =TRUE() -> TRUE
A35: What is Jagoda Draženović's gender? | B35: FEMALE. | C35: =TRUE() -> TRUE | E35: =TRUE() -> TRUE
A36: List all Jagoda Draženović's friends. | B36: 0, 4 | C36: half true | E36: half true
A37: How many friends does Jagoda Draženović have? | B37: 2 | C37: =TRUE() -> TRUE | E37: =TRUE() -> TRUE
A38: What is Monika Rimac's first name? | B38: Monika. | C38: =TRUE() -> TRUE | E38: =TRUE() -> TRUE
A39: What is Monika Rimac's last name? | B39: Rimac | C39: =TRUE() -> TRUE | E39: =TRUE() -> TRUE
A40: What is Monika Rimac's age? | B40: 10 | C40: =TRUE() -> TRUE | E40: =TRUE() -> TRUE
...

Sheet foaf_names.xml
A1: prompt | B1: answer | C1: validity | D1: note | E1: validity_ds
A2: What is Saša Škrtić's first name? | B2: Saša | C2: =TRUE() -> TRUE | E2: =TRUE() -> TRUE
A3: What is Saša Škrtić's last name? | B3: Škrtić | C3: =TRUE() -> TRUE | E3: =TRUE() -> TRUE
A4: What is Saša Škrtić's age? | B4: 17 | C4: =TRUE() -> TRUE | E4: =TRUE() -> TRUE
A5: What is Saša Škrtić's gender? | B5: MALE | C5: =TRUE() -> TRUE | E5: =TRUE() -> TRUE
A6: List all Saša Škrtić's friends. | B6: Duje Ravlić, Zoran Goreta | C6: half true | E6: half true
A7: How many friends does Saša Škrtić have? | B7: 4 | C7: =TRUE() -> TRUE | E7: TRUE
A8: What is Duje Ravlić's first name? | B8: Duje | C8: =TRUE() -> TRUE | E8: =TRUE() -> TRUE
A9: What is Duje Ravlić's last name? | B9: Ravlić. | C9: =TRUE() -> TRUE | E9: =TRUE() -> TRUE
A10: What is Duje Ravlić's age? | B10: 18 | C10: =TRUE() -> TRUE | E10: =TRUE() -> TRUE
A11: What is Duje Ravlić's gender? | B11: MALE | C11: =TRUE() -> TRUE | E11: =TRUE() -> TRUE
A12: List all Duje Ravlić's friends. | B12: Duje Ravlić's friends: 1. | C12: =FALSE() -> FALSE | E12: FALSE
A13: How many friends does Duje Ravlić have? | B13: Duje Ravlić has 6 friends. | C13: =FALSE() -> FALSE | E13: FALSE
A14: What is Eduard Tutić's first name? | B14: Eduard | C14: =TRUE() -> TRUE | E14: =TRUE() -> TRUE
A15: What is Eduard Tutić's last name? | B15: Tutić | C15: =TRUE() -> TRUE | E15: =TRUE() -> TRUE
A16: What is Eduard Tutić's age? | B16: 21 | C16: =TRUE() -> TRUE | E16: =TRUE() -> TRUE
A17: What is Eduard Tutić's gender? | B17: MALE | C17: =TRUE() -> TRUE | E17: =TRUE() -> TRUE
A18: List all Eduard Tutić's friends. | B18: Eduard Tutić's friends: - | C18: =FALSE() -> FALSE | E18: FALSE
A19: How many friends does Eduard Tutić have? | B19: 7 | C19: =FALSE() -> FALSE | E19: FALSE
A20: What is Zoran Goreta's first name? | B20: Zoran | C20: =TRUE() -> TRUE | E20: =TRUE() -> TRUE
A21: What is Zoran Goreta's last name? | B21: Goreta. | C21: =TRUE() -> TRUE | E21: =TRUE() -> TRUE
A22: What is Zoran Goreta's age? | B22: 39 | C22: =TRUE() -> TRUE | E22: =TRUE() -> TRUE
A23: What is Zoran Goreta's gender? | B23: MALE | C23: =TRUE() -> TRUE | E23: =TRUE() -> TRUE
A24: List all Zoran Goreta's friends. | B24: Saša Škrtić, Eduard | C24: =TRUE() -> TRUE | E24: TRUE
A25: How many friends does Zoran Goreta have? | B25: 2 | C25: =TRUE() -> TRUE | E25: TRUE
A26: What is Ivo Čelina's first name? | B26: Ivo | C26: =TRUE() -> TRUE | E26: =TRUE() -> TRUE
A27: What is Ivo Čelina's last name? | B27: Čelina. | C27: =TRUE() -> TRUE | E27: =TRUE() -> TRUE
A28: What is Ivo Čelina's age? | B28: 24 | C28: =TRUE() -> TRUE | E28: =TRUE() -> TRUE
A29: What is Ivo Čelina's gender? | B29: MALE | C29: =TRUE() -> TRUE | E29: =TRUE() -> TRUE
A30: List all Ivo Čelina's friends. | B30: Duje Ravlić, Eduard Tuti | C30: half true | E30: half true
A31: How many friends does Ivo Čelina have? | B31: Ivo Čelina has 3 friends. | C31: =TRUE() -> TRUE | E31: TRUE
A32: What is Jagoda Draženović's first name? | B32: Jagoda. | C32: =TRUE() -> TRUE | E32: =TRUE() -> TRUE
A33: What is Jagoda Draženović's last name? | B33: Draženović | C33: =TRUE() -> TRUE | E33: =TRUE() -> TRUE
A34: What is Jagoda Draženović's age? | B34: 11 | C34: =TRUE() -> TRUE | E34: =TRUE() -> TRUE
A35: What is Jagoda Draženović's gender? | B35: FEMALE | C35: =TRUE() -> TRUE | E35: =TRUE() -> TRUE
A36: List all Jagoda Draženović's friends. | B36: Saša Škrtić, Ivo | C36: =TRUE() -> TRUE | E36: TRUE
A37: How many friends does Jagoda Draženović have? | B37: 2 | C37: =TRUE() -> TRUE | E37: TRUE
A38: What is Monika Rimac's first name? | B38: Monika. | C38: =TRUE() -> TRUE | E38: =TRUE() -> TRUE
A39: What is Monika Rimac's last name? | B39: Rimac. | C39: =TRUE() -> TRUE | E39: =TRUE() -> TRUE
A40: What is Monika Rimac's age? | B40: 10 | C40: =TRUE() -> TRUE | E40: =TRUE() -> TRUE
...

Sheet foaf_names.rdf
A1: prompt | B1: answer | C1: validity | D1: note | E1: validity_ds
A2: What is Saša Škrtić's first name? | B2: Saša | C2: =TRUE() -> TRUE | E2: TRUE
A3: What is Saša Škrtić's last name? | B3: Škrtić. | C3: =TRUE() -> TRUE | E3: TRUE
A4: What is Saša Škrtić's age? | B4: 17 | C4: =TRUE() -> TRUE | E4: TRUE
A5: What is Saša Škrtić's gender? | B5: MALE | C5: =TRUE() -> TRUE | E5: TRUE
A6: List all Saša Škrtić's friends. | B6: Duje Ravlić, Zoran Goreta | C6: half true | E6: half true
A7: How many friends does Saša Škrtić have? | B7: 6 | C7: =FALSE() -> FALSE | E7: FALSE
A8: What is Duje Ravlić's first name? | B8: Duje | C8: =TRUE() -> TRUE | E8: TRUE
A9: What is Duje Ravlić's last name? | B9: Ravlić | C9: =TRUE() -> TRUE | E9: TRUE
A10: What is Duje Ravlić's age? | B10: 18 | C10: =TRUE() -> TRUE | E10: TRUE
A11: What is Duje Ravlić's gender? | B11: MALE | C11: =TRUE() -> TRUE | E11: TRUE
A12: List all Duje Ravlić's friends. | B12: Duje Ravlić's friends: 1. | C12: =FALSE() -> FALSE | E12: FALSE
A13: How many friends does Duje Ravlić have? | B13: 8 | C13: =FALSE() -> FALSE | E13: FALSE
A14: What is Eduard Tutić's first name? | B14: Eduard | C14: =TRUE() -> TRUE | E14: TRUE
A15: What is Eduard Tutić's last name? | B15: Tutić | C15: =TRUE() -> TRUE | E15: TRUE
A16: What is Eduard Tutić's age? | B16: 21. | C16: =TRUE() -> TRUE | E16: TRUE
A17: What is Eduard Tutić's gender? | B17: MALE | C17: =TRUE() -> TRUE | E17: TRUE
A18: List all Eduard Tutić's friends. | B18: Eduard Tutić's friends: | C18: =FALSE() -> FALSE | E18: FALSE
A19: How many friends does Eduard Tutić have? | B19: 8. | C19: =FALSE() -> FALSE | E19: FALSE
A20: What is Zoran Goreta's first name? | B20: Zoran | C20: =TRUE() -> TRUE | E20: TRUE
A21: What is Zoran Goreta's last name? | B21: Goreta | C21: =TRUE() -> TRUE | E21: TRUE
A22: What is Zoran Goreta's age? | B22: 39. | C22: =TRUE() -> TRUE | E22: TRUE
A23: What is Zoran Goreta's gender? | B23: MALE | C23: =TRUE() -> TRUE | E23: TRUE
A24: List all Zoran Goreta's friends. | B24: Saša Škrtić, Eduard | C24: =TRUE() -> TRUE | E24: =TRUE() -> TRUE
A25: How many friends does Zoran Goreta have? | B25: 2 | C25: =TRUE() -> TRUE | E25: =TRUE() -> TRUE
A26: What is Ivo Čelina's first name? | B26: Ivo. | C26: =TRUE() -> TRUE | E26: TRUE
A27: What is Ivo Čelina's last name? | B27: Čelina. | C27: =TRUE() -> TRUE | E27: TRUE
A28: What is Ivo Čelina's age? | B28: 24 | C28: =TRUE() -> TRUE | E28: TRUE
A29: What is Ivo Čelina's gender? | B29: MALE | C29: =TRUE() -> TRUE | E29: TRUE
A30: List all Ivo Čelina's friends. | B30: Duje Ravlić, Eduard Tuti | C30: half true | E30: half true
A31: How many friends does Ivo Čelina have? | B31: He has 3 friends. | C31: =TRUE() -> TRUE | E31: TRUE
A32: What is Jagoda Draženović's first name? | B32: Jagoda | C32: =TRUE() -> TRUE | E32: TRUE
A33: What is Jagoda Draženović's last name? | B33: Draženović | C33: =TRUE() -> TRUE | E33: TRUE
A34: What is Jagoda Draženović's age? | B34: 11 | C34: =TRUE() -> TRUE | E34: TRUE
A35: What is Jagoda Draženović's gender? | B35: FEMALE. | C35: =TRUE() -> TRUE | E35: TRUE
A36: List all Jagoda Draženović's friends. | B36: Saša Škrtić, Ivo | C36: =TRUE() -> TRUE | E36: TRUE
A37: How many friends does Jagoda Draženović have? | B37: 2. | C37: =TRUE() -> TRUE | E37: TRUE
A38: What is Monika Rimac's first name? | B38: Monika | C38: =TRUE() -> TRUE | E38: TRUE
A39: What is Monika Rimac's last name? | B39: Rimac | C39: =TRUE() -> TRUE | E39: TRUE
A40: What is Monika Rimac's age? | B40: 10 | C40: =TRUE() -> TRUE | E40: TRUE
...

Sheet foaf_names.json
A1: prompt | B1: answer | C1: validity | D1: note | E1: validity_ds
A2: What is Saša Škrtić's first name? | B2: Saša | C2: =TRUE() -> TRUE | E2: TRUE
A3: What is Saša Škrtić's last name? | B3: Škrtić | C3: =TRUE() -> TRUE | E3: TRUE
A4: What is Saša Škrtić's age? | B4: 17 | C4: =TRUE() -> TRUE | E4: TRUE
A5: What is Saša Škrtić's gender? | B5: MALE | C5: =TRUE() -> TRUE | E5: TRUE
A6: List all Saša Škrtić's friends. | B6: ["Duje Ravlić", "Zoran | C6: half true | E6: half true
A7: How many friends does Saša Škrtić have? | B7: 4 | C7: =TRUE() -> TRUE | E7: TRUE
A8: What is Duje Ravlić's first name? | B8: Duje | C8: =TRUE() -> TRUE | E8: TRUE
A9: What is Duje Ravlić's last name? | B9: Ravlić | C9: =TRUE() -> TRUE | E9: TRUE
A10: What is Duje Ravlić's age? | B10: 18 | C10: =TRUE() -> TRUE | E10: TRUE
A11: What is Duje Ravlić's gender? | B11: MALE | C11: =TRUE() -> TRUE | E11: TRUE
A12: List all Duje Ravlić's friends. | B12: Duje Ravlić's friends: 1. | C12: =FALSE() -> FALSE | E12: FALSE
A13: How many friends does Duje Ravlić have? | B13: Duje Ravlić has 3 friends. | C13: =TRUE() -> TRUE | E13: TRUE
A14: What is Eduard Tutić's first name? | B14: Eduard | C14: =TRUE() -> TRUE | E14: TRUE
A15: What is Eduard Tutić's last name? | B15: Tutić | C15: =TRUE() -> TRUE | E15: TRUE
A16: What is Eduard Tutić's age? | B16: 21 | C16: =TRUE() -> TRUE | E16: TRUE
A17: What is Eduard Tutić's gender? | B17: MALE | C17: =TRUE() -> TRUE | E17: TRUE
A18: List all Eduard Tutić's friends. | B18: [ {"friend": "Zoran Goreta | C18: half true | E18: half true
A19: How many friends does Eduard Tutić have? | B19: Eduard Tutić has 4 friends | C19: =TRUE() -> TRUE | E19: TRUE
A20: What is Zoran Goreta's first name? | B20: Zoran | C20: =TRUE() -> TRUE | E20: TRUE
A21: What is Zoran Goreta's last name? | B21: Goreta. | C21: =TRUE() -> TRUE | E21: TRUE
A22: What is Zoran Goreta's age? | B22: 39 | C22: =TRUE() -> TRUE | E22: TRUE
A23: What is Zoran Goreta's gender? | B23: MALE | C23: =TRUE() -> TRUE | E23: TRUE
A24: List all Zoran Goreta's friends. | B24: Saša Škrtić, Eduard | C24: =TRUE() -> TRUE | E24: TRUE
A25: How many friends does Zoran Goreta have? | B25: 2 | C25: =TRUE() -> TRUE | E25: TRUE
A26: What is Ivo Čelina's first name? | B26: Ivo | C26: =TRUE() -> TRUE | E26: TRUE
A27: What is Ivo Čelina's last name? | B27: Čelina | C27: =TRUE() -> TRUE | E27: TRUE
A28: What is Ivo Čelina's age? | B28: 24 | C28: =TRUE() -> TRUE | E28: TRUE
A29: What is Ivo Čelina's gender? | B29: MALE | C29: =TRUE() -> TRUE | E29: TRUE
A30: List all Ivo Čelina's friends. | B30: Duje Ravlić, Eduard Tuti | C30: half true | E30: half true
A31: How many friends does Ivo Čelina have? | B31: Ivo Čelina has 3 friends. | C31: =TRUE() -> TRUE | E31: TRUE
A32: What is Jagoda Draženović's first name? | B32: Jagoda | C32: =TRUE() -> TRUE | E32: TRUE
A33: What is Jagoda Draženović's last name? | B33: Draženović | C33: =TRUE() -> TRUE | E33: TRUE
A34: What is Jagoda Draženović's age? | B34: 11 | C34: =TRUE() -> TRUE | E34: TRUE
A35: What is Jagoda Draženović's gender? | B35: FEMALE. | C35: =TRUE() -> TRUE | E35: TRUE
A36: List all Jagoda Draženović's friends. | B36: Ivo Čelina, Jagoda Dražen | C36: half true | E36: FALSE
A37: How many friends does Jagoda Draženović have? | B37: 2 | C37: =TRUE() -> TRUE | E37: TRUE
A38: What is Monika Rimac's first name? | B38: Monika | C38: =TRUE() -> TRUE | E38: TRUE
A39: What is Monika Rimac's last name? | B39: Rimac | C39: =TRUE() -> TRUE | E39: TRUE
A40: What is Monika Rimac's age? | B40: 10 | C40: =TRUE() -> TRUE | E40: TRUE
...

Sheet natural.json
A1: prompt | B1: answer | C1: validity | D1: note | E1: validity_ds
A2: What is Saša Škrtić's first name? | B2: Not mentioned. | C2: =FALSE() -> FALSE | E2: FALSE
A3: What is Saša Škrtić's last name? | B3: Škrtić | C3: =TRUE() -> TRUE | E3: TRUE
A4: What is Saša Škrtić's age? | B4: 17 | C4: =TRUE() -> TRUE | E4: TRUE
A5: What is Saša Škrtić's gender? | B5: Male. | C5: =TRUE() -> TRUE | E5: TRUE
A6: List all Saša Škrtić's friends. | B6: Duje Ravlić, Zoran Goreta | C6: half true | E6: half true
A7: How many friends does Saša Škrtić have? | B7: 7 | C7: =FALSE() -> FALSE | E7: FALSE
A8: What is Duje Ravlić's first name? | B8: There is no mention of Duje Ravlić | C8: =FALSE() -> FALSE | E8: FALSE
A9: What is Duje Ravlić's last name? | B9: Ravlić | C9: =TRUE() -> TRUE | E9: TRUE
A10: What is Duje Ravlić's age? | B10: 18 years old. | C10: =TRUE() -> TRUE | E10: TRUE
A11: What is Duje Ravlić's gender? | B11: Male. | C11: =TRUE() -> TRUE | E11: TRUE
A12: List all Duje Ravlić's friends. | B12: Saša Škrtić, Ivo | C12: half true | E12: half true
A13: How many friends does Duje Ravlić have? | B13: 6 | C13: =FALSE() -> FALSE | E13: FALSE
A14: What is Eduard Tutić's first name? | B14: Data does not provide Eduard Tutić's | C14: =FALSE() -> FALSE | E14: FALSE
A15: What is Eduard Tutić's last name? | B15: Tutić | C15: =TRUE() -> TRUE | E15: TRUE
A16: What is Eduard Tutić's age? | B16: 21 years old. | C16: =TRUE() -> TRUE | E16: TRUE
A17: What is Eduard Tutić's gender? | B17: Male. | C17: =TRUE() -> TRUE | E17: TRUE
A18: List all Eduard Tutić's friends. | B18: Eduard Tutić's friends: | C18: =FALSE() -> FALSE | E18: FALSE
A19: How many friends does Eduard Tutić have? | B19: 6 | C19: =FALSE() -> FALSE | E19: FALSE
A20: What is Zoran Goreta's first name? | B20: Zoran. | C20: =TRUE() -> TRUE | E20: TRUE
A21: What is Zoran Goreta's last name? | B21: Goreta. | C21: =TRUE() -> TRUE | E21: TRUE
A22: What is Zoran Goreta's age? | B22: 39 | C22: =TRUE() -> TRUE | E22: TRUE
A23: What is Zoran Goreta's gender? | B23: Male. | C23: =TRUE() -> TRUE | E23: TRUE
A24: List all Zoran Goreta's friends. | B24: Saša Škrtić, Eduard | C24: =TRUE() -> TRUE | E24: TRUE
A25: How many friends does Zoran Goreta have? | B25: 2 | C25: =TRUE() -> TRUE | E25: TRUE
A26: What is Ivo Čelina's first name? | B26: Ivo. | C26: =TRUE() -> TRUE | E26: TRUE
A27: What is Ivo Čelina's last name? | B27: Ivo's last name is Čelina. | C27: =TRUE() -> TRUE | E27: TRUE
A28: What is Ivo Čelina's age? | B28: 24 | C28: =TRUE() -> TRUE | E28: TRUE
A29: What is Ivo Čelina's gender? | B29: Male. | C29: =TRUE() -> TRUE | E29: TRUE
A30: List all Ivo Čelina's friends. | B30: Duje Ravlić, Eduard Tuti | C30: half true | E30: half true
A31: How many friends does Ivo Čelina have? | B31: 6 | C31: =FALSE() -> FALSE | E31: FALSE
A32: What is Jagoda Draženović's first name? | B32: Jagoda | C32: =TRUE() -> TRUE | E32: TRUE
A33: What is Jagoda Draženović's last name? | B33: Draženović | C33: =TRUE() -> TRUE | E33: TRUE
A34: What is Jagoda Draženović's age? | B34: 11 | C34: =TRUE() -> TRUE | E34: TRUE
A35: What is Jagoda Draženović's gender? | B35: Female. | C35: =TRUE() -> TRUE | E35: TRUE
A36: List all Jagoda Draženović's friends. | B36: Ivo Čelina, Jagoda Dražen | C36: half true | E36: half true
A37: How many friends does Jagoda Draženović have? | B37: 3 | C37: =FALSE() -> FALSE | E37: FALSE
A38: What is Monika Rimac's first name? | B38: Monika | C38: =TRUE() -> TRUE | E38: TRUE
A39: What is Monika Rimac's last name? | B39: Rimac | C39: =TRUE() -> TRUE | E39: TRUE
A40: What is Monika Rimac's age? | B40: 10 | C40: =TRUE() -> TRUE | E40: TRUE
...
